<?xml version='1.0' encoding='UTF-8'?>
<robot name="stretch_full">
  <link name="virtual_base_link">
    <inertial>
      <origin xyz="0.0 0.0 0.0" rpy="0.0 -0.0 0.0"/>
      <mass value="1.0"/>
      <inertia ixx="1.0" ixy="0.0" ixz="0.0" iyy="1.0" iyz="0.0" izz="1.0"/>
    </inertial>
  </link>
  <link name="x_virtual_link">
    <inertial>
      <origin xyz="0.0 0.0 0.0" rpy="0.0 -0.0 0.0"/>
      <mass value="1.0"/>
      <inertia ixx="1.0" ixy="0.0" ixz="0.0" iyy="1.0" iyz="0.0" izz="1.0"/>
    </inertial>
  </link>
  <link name="y_virtual_link">
    <inertial>
      <origin xyz="0.0 0.0 0.0" rpy="0.0 -0.0 0.0"/>
      <mass value="1.0"/>
      <inertia ixx="1.0" ixy="0.0" ixz="0.0" iyy="1.0" iyz="0.0" izz="1.0"/>
    </inertial>
  </link>
  <link name="z_virtual_link">
    <inertial>
      <origin xyz="0.0 0.0 0.0" rpy="0.0 -0.0 0.0"/>
      <mass value="1.0"/>
      <inertia ixx="1.0" ixy="0.0" ixz="0.0" iyy="1.0" iyz="0.0" izz="1.0"/>
    </inertial>
  </link>
  <link name="base_link">
    <inertial>
      <origin xyz="-0.087526 -0.001626 0.081009" rpy="0.0 0.0 0.0"/>
      <mass value="17.384389"/>
      <inertia ixx="0.160002" ixy="0.006758" ixz="0.004621" iyy="0.138068" iyz="0.002208" izz="0.228992"/>
    </inertial>
    <visual>
      <geometry>
        <mesh filename="./meshes/base_link.STL"/>
      </geometry>
      <material name=""/>
      <origin xyz="0.0 0.0 0.0" rpy="0.0 0.0 0.0"/>
    </visual>
    <collision>
      <geometry>
        <mesh filename="./meshes/base_link_collision.STL"/>
      </geometry>
      <origin xyz="0.0 0.0 0.0" rpy="0.0 0.0 0.0"/>
    </collision>
  </link>
  <link name="link_mast">
    <inertial>
      <origin xyz="0.000337 0.722201 0.002652" rpy="0.0 0.0 0.0"/>
      <mass value="1.764017"/>
      <inertia ixx="0.291286" ixy="0.004149" ixz="-0.000174" iyy="0.001226" iyz="0.000354" izz="0.291429"/>
    </inertial>
    <visual>
      <geometry>
        <mesh filename="./meshes/link_mast.STL"/>
      </geometry>
      <material name=""/>
      <origin xyz="0.0 0.0 0.0" rpy="0.0 0.0 0.0"/>
    </visual>
    <collision>
      <geometry>
        <mesh filename="./meshes/link_mast_collision.STL"/>
      </geometry>
      <origin xyz="0.0 0.0 0.0" rpy="0.0 0.0 0.0"/>
    </collision>
  </link>
  <link name="link_lift">
    <inertial>
      <origin xyz="-0.020369 0.03438 0.02236" rpy="0.0 0.0 0.0"/>
      <mass value="1.987167"/>
      <inertia ixx="0.006518" ixy="-0.001539" ixz="0.000371" iyy="0.004464" iyz="0.000392" izz="0.008092"/>
    </inertial>
    <visual>
      <geometry>
        <mesh filename="./meshes/link_lift.STL"/>
      </geometry>
      <material name=""/>
      <origin xyz="0.0 0.0 0.0" rpy="0.0 0.0 0.0"/>
    </visual>
    <collision>
      <geometry>
        <mesh filename="./meshes/link_lift_collision.STL"/>
      </geometry>
      <origin xyz="0.0 0.0 0.0" rpy="0.0 0.0 0.0"/>
    </collision>
  </link>
  <link name="link_arm_l4">
    <inertial>
      <origin xyz="-0.000168 -0.000254 -0.125235" rpy="0.0 0.0 0.0"/>
      <mass value="0.235626"/>
      <inertia ixx="0.001518" ixy="-1e-06" ixz="3e-06" iyy="0.001519" iyz="3e-06" izz="0.000176"/>
    </inertial>
    <visual>
      <geometry>
        <mesh filename="./meshes/link_arm_l4.STL"/>
      </geometry>
      <material name=""/>
      <origin xyz="0.0 0.0 0.0" rpy="0.0 0.0 0.0"/>
    </visual>
    <collision>
      <geometry>
        <mesh filename="./meshes/link_arm_l4_collision.STL"/>
      </geometry>
      <origin xyz="0.0 0.0 0.0" rpy="0.0 0.0 0.0"/>
    </collision>
  </link>
  <link name="link_arm_l3">
    <inertial>
      <origin xyz="-1e-06 -0.000146 -0.11908" rpy="0.0 0.0 0.0"/>
      <mass value="0.146817"/>
      <inertia ixx="0.001081" ixy="0.0" ixz="0.0" iyy="0.001081" iyz="-1e-06" izz="7.7e-05"/>
    </inertial>
    <visual>
      <geometry>
        <mesh filename="./meshes/link_arm_l3.STL"/>
      </geometry>
      <material name=""/>
      <origin xyz="0.0 0.0 0.0" rpy="0.0 0.0 0.0"/>
    </visual>
    <collision>
      <geometry>
        <mesh filename="./meshes/link_arm_l3_collision.STL"/>
      </geometry>
      <origin xyz="0.0 0.0 0.0" rpy="0.0 0.0 0.0"/>
    </collision>
  </link>
  <link name="link_arm_l2">
    <inertial>
      <origin xyz="0.0 -7.1e-05 -0.115635" rpy="0.0 0.0 0.0"/>
      <mass value="0.130565"/>
      <inertia ixx="0.000943" ixy="0.0" ixz="0.0" iyy="0.000943" iyz="0.0" izz="5.7e-05"/>
    </inertial>
    <visual>
      <geometry>
        <mesh filename="./meshes/link_arm_l2.STL"/>
      </geometry>
      <material name=""/>
      <origin xyz="0.0 0.0 0.0" rpy="0.0 0.0 0.0"/>
    </visual>
    <collision>
      <geometry>
        <mesh filename="./meshes/link_arm_l2_collision.STL"/>
      </geometry>
      <origin xyz="0.0 0.0 0.0" rpy="0.0 0.0 0.0"/>
    </collision>
  </link>
  <link name="link_arm_l1">
    <inertial>
      <origin xyz="-1e-06 -0.000121 -0.113457" rpy="0.0 0.0 0.0"/>
      <mass value="0.113658"/>
      <inertia ixx="0.0008" ixy="0.0" ixz="0.0" iyy="0.0008" iyz="0.0" izz="4e-05"/>
    </inertial>
    <visual>
      <geometry>
        <mesh filename="./meshes/link_arm_l1.STL"/>
      </geometry>
      <material name=""/>
      <origin xyz="0.0 0.0 0.0" rpy="0.0 0.0 0.0"/>
    </visual>
    <collision>
      <geometry>
        <mesh filename="./meshes/link_arm_l1_collision.STL"/>
      </geometry>
      <origin xyz="0.0 0.0 0.0" rpy="0.0 0.0 0.0"/>
    </collision>
  </link>
  <link name="link_arm_l0">
    <inertial>
      <origin xyz="0.033681 -0.000847 -0.031723" rpy="0.0 0.0 0.0"/>
      <mass value="0.427734"/>
      <inertia ixx="0.001689" ixy="-2.8e-05" ixz="0.000483" iyy="0.002107" iyz="-1.1e-05" izz="0.000571"/>
    </inertial>
    <visual>
      <geometry>
        <mesh filename="./meshes/link_arm_l0.STL"/>
      </geometry>
      <material name=""/>
      <origin xyz="0.0 0.0 0.0" rpy="0.0 0.0 0.0"/>
    </visual>
    <collision>
      <geometry>
        <mesh filename="./meshes/link_arm_l0_collision.STL"/>
      </geometry>
      <origin xyz="0.0 0.0 0.0" rpy="0.0 0.0 0.0"/>
    </collision>
  </link>
  <link name="link_wrist_yaw">
    <inertial>
      <origin xyz="0.0 -3.9e-05 -0.016495" rpy="0.0 0.0 0.0"/>
      <mass value="0.054422"/>
      <inertia ixx="9e-06" ixy="0.0" ixz="0.0" iyy="9e-06" iyz="0.0" izz="7e-06"/>
    </inertial>
    <visual>
      <geometry>
        <mesh filename="./meshes/link_wrist_yaw.STL"/>
      </geometry>
      <material name=""/>
      <origin xyz="0.0 0.0 0.0" rpy="0.0 0.0 0.0"/>
    </visual>
    <collision>
      <geometry>
        <mesh filename="./meshes/link_wrist_yaw_collision.STL"/>
      </geometry>
      <origin xyz="0.0 0.0 0.0" rpy="0.0 0.0 0.0"/>
    </collision>
  </link>
  <link name="link_wrist_yaw_bottom">
    <inertial>
      <origin xyz="-0.0165399153795968 -0.0446328107020906 -0.0281087384763343" rpy="0.0 0.0 0.0"/>
      <mass value="0.144548635554334"/>
      <inertia ixx="4.56525957614798e-05" ixy="-1.08217417869179e-06" ixz="-1.44384040297111e-08" iyy="7.22875259104698e-05" iyz="3.40820143544021e-09" izz="8.76544308203217e-05"/>
    </inertial>
    <visual>
      <geometry>
        <mesh filename="./meshes/link_DW3_wrist_yaw_bottom.STL"/>
      </geometry>
      <material name=""/>
      <origin xyz="0.0 0.0 0.0" rpy="0.0 0.0 0.0"/>
    </visual>
    <collision>
      <geometry>
        <mesh filename="./meshes/link_DW3_wrist_yaw_bottom_collision.STL"/>
      </geometry>
      <origin xyz="0.0 0.0 0.0" rpy="0.0 0.0 0.0"/>
    </collision>
  </link>
  <link name="link_wrist_pitch">
    <inertial>
      <origin xyz="-0.000711479645697954 -0.0147442681465562 0.0195140764319514" rpy="0.0 0.0 0.0"/>
      <mass value="0.116590512374845"/>
      <inertia ixx="5.76204624498191e-05" ixy="-7.78647509857216e-07" ixz="-2.86646997376633e-08" iyy="3.5844353951621e-05" iyz="1.06445058968725e-06" izz="6.36355321976534e-05"/>
    </inertial>
    <visual>
      <geometry>
        <mesh filename="./meshes/link_DW3_wrist_pitch.STL"/>
      </geometry>
      <material name=""/>
      <origin xyz="0.0 0.0 0.0" rpy="0.0 0.0 0.0"/>
    </visual>
    <collision>
      <geometry>
        <mesh filename="./meshes/link_DW3_wrist_pitch_collision.STL"/>
      </geometry>
      <origin xyz="0.0 0.0 0.0" rpy="0.0 0.0 0.0"/>
    </collision>
  </link>
  <link name="link_wrist_roll">
    <inertial>
      <origin xyz="0.000282866582415386 0.000557472767112266 0.0196635450480892" rpy="0.0 0.0 0.0"/>
      <mass value="0.0221916689638078"/>
      <inertia ixx="2.20608319376175e-06" ixy="3.01742816614342e-09" ixz="-1.83537060988685e-08" iyy="2.91436292743443e-06" iyz="-4.5509705441618e-08" izz="4.83731409646016e-06"/>
    </inertial>
    <visual>
      <geometry>
        <mesh filename="./meshes/link_DW3_wrist_roll.STL"/>
      </geometry>
      <material name=""/>
      <origin xyz="0.0 0.0 0.0" rpy="0.0 0.0 0.0"/>
    </visual>
    <collision>
      <geometry>
        <mesh filename="./meshes/link_DW3_wrist_roll_collision.STL"/>
      </geometry>
      <origin xyz="0.0 0.0 0.0" rpy="0.0 0.0 0.0"/>
    </collision>
  </link>
  <link name="link_gripper_s3_body">
    <inertial>
      <origin xyz="0.000296364207693828 0.00742489472460528 0.0440194148825503" rpy="0.0 0.0 0.0"/>
      <mass value="0.288995995074102"/>
      <inertia ixx="0.000482695285602815" ixy="-3.02029982967392e-06" ixz="6.73858128561175e-07" iyy="0.000213430693267808" iyz="-1.95797907844847e-05" izz="0.000377638305434195"/>
    </inertial>
    <visual>
      <geometry>
        <mesh filename="./meshes/link_SG3_gripper_body.STL"/>
      </geometry>
      <material name=""/>
      <origin xyz="0.0 0.0 0.0" rpy="0.0 0.0 0.0"/>
    </visual>
    <collision>
      <geometry>
        <mesh filename="./meshes/link_SG3_gripper_body_collision.STL"/>
      </geometry>
      <origin xyz="0.0 0.0 0.0" rpy="0.0 0.0 0.0"/>
    </collision>
  </link>
  <link name="link_gripper_finger_right">
    <inertial>
      <origin xyz="-0.107294725536829 -0.00404012121215261 7.86433341395387e-05" rpy="0.0 0.0 0.0"/>
      <mass value="0.0483698337858479"/>
      <inertia ixx="3.0603544296956e-06" ixy="-8.13967524445937e-07" ixz="-6.04746355450675e-08" iyy="6.12306677697621e-05" iyz="-1.81592899124487e-08" izz="6.24670188075471e-05"/>
    </inertial>
    <visual>
      <geometry>
        <mesh filename="./meshes/link_SG3_gripper_finger_right.STL"/>
      </geometry>
      <material name=""/>
      <origin xyz="0.0 0.0 0.0" rpy="0.0 0.0 0.0"/>
    </visual>
    <collision>
      <geometry>
        <mesh filename="./meshes/link_SG3_gripper_finger_right_collision.STL"/>
      </geometry>
      <origin xyz="0.0 0.0 0.0" rpy="0.0 0.0 0.0"/>
    </collision>
  </link>
  <link name="link_gripper_fingertip_right">
    <inertial>
      <origin xyz="2.8647736627363e-08 -9.47712436305537e-09 0.00812577933915037" rpy="0.0 0.0 0.0"/>
      <mass value="0.00382162062525088"/>
      <inertia ixx="4.13411802118931e-07" ixy="3.48038363075757e-16" ixz="-5.14102948448996e-13" iyy="4.13411799815932e-07" iyz="1.76223254858882e-13" izz="7.08442016110623e-07"/>
    </inertial>
    <visual>
      <geometry>
        <mesh filename="./meshes/link_SG3_gripper_fingertip_right.STL"/>
      </geometry>
      <material name=""/>
      <origin xyz="0.0 0.0 0.0" rpy="0.0 0.0 0.0"/>
    </visual>
    <collision>
      <geometry>
        <mesh filename="./meshes/link_SG3_gripper_fingertip_right_collision.STL"/>
      </geometry>
      <origin xyz="0.0 0.0 0.0" rpy="0.0 0.0 0.0"/>
    </collision>
  </link>
  <link name="link_gripper_finger_left">
    <inertial>
      <origin xyz="0.107294715994863 -0.00404011929289155 7.86443400617731e-05" rpy="0.0 0.0 0.0"/>
      <mass value="0.0483698266031602"/>
      <inertia ixx="3.06035472000871e-06" ixy="8.13968102368407e-07" ixz="6.04787443258659e-08" iyy="6.12306675643124e-05" iyz="-1.81596824851191e-08" izz="6.24670194741309e-05"/>
    </inertial>
    <visual>
      <geometry>
        <mesh filename="./meshes/link_SG3_gripper_finger_left.STL"/>
      </geometry>
      <material name=""/>
      <origin xyz="0.0 0.0 0.0" rpy="0.0 0.0 0.0"/>
    </visual>
    <collision>
      <geometry>
        <mesh filename="./meshes/link_SG3_gripper_finger_left_collision.STL"/>
      </geometry>
      <origin xyz="0.0 0.0 0.0" rpy="0.0 0.0 0.0"/>
    </collision>
  </link>
  <link name="link_gripper_fingertip_left">
    <inertial>
      <origin xyz="-3.08483497635237e-08 -1.26956833934599e-09 0.0081257795407928" rpy="0.0 0.0 0.0"/>
      <mass value="0.00382162054362131"/>
      <inertia ixx="4.13411804417319e-07" ixy="2.60118266065524e-16" ixz="5.82035131405725e-13" iyy="4.13411805017951e-07" iyz="2.22196449834679e-14" izz="7.08442015318697e-07"/>
    </inertial>
    <visual>
      <geometry>
        <mesh filename="./meshes/link_SG3_gripper_fingertip_left.STL"/>
      </geometry>
      <material name=""/>
      <origin xyz="0.0 0.0 0.0" rpy="0.0 0.0 0.0"/>
    </visual>
    <collision>
      <geometry>
        <mesh filename="./meshes/link_SG3_gripper_fingertip_left_collision.STL"/>
      </geometry>
      <origin xyz="0.0 0.0 0.0" rpy="0.0 0.0 0.0"/>
    </collision>
  </link>
  <link name="link_grasp_center">
    <inertial>
      <origin xyz="0.0 0.0 0.0" rpy="0.0 -0.0 0.0"/>
      <mass value="1.0"/>
      <inertia ixx="1.0" ixy="0.0" ixz="0.0" iyy="1.0" iyz="0.0" izz="1.0"/>
    </inertial>
  </link>
  <joint name="virtual_base_joint" type="fixed">
    <parent link="z_virtual_link"/>
    <child link="base_link"/>
    <axis xyz="1. 0. 0."/>
    <origin xyz="0.0 0.0 0.0" rpy="0.0 -0.0 0.0"/>
  </joint>
  <joint name="x_prismatic_joint" type="prismatic">
    <limit effort="10.0" velocity="1.0" lower="-100.0" upper="100.0"/>
    <parent link="virtual_base_link"/>
    <child link="x_virtual_link"/>
    <axis xyz="1. 0. 0."/>
    <origin xyz="0.0 0.0 0.0" rpy="0.0 -0.0 0.0"/>
  </joint>
  <joint name="y_prismatic_joint" type="prismatic">
    <limit effort="10.0" velocity="1.0" lower="-100.0" upper="100.0"/>
    <parent link="x_virtual_link"/>
    <child link="y_virtual_link"/>
    <axis xyz="0. 1. 0."/>
    <origin xyz="0.0 0.0 0.0" rpy="0.0 -0.0 0.0"/>
  </joint>
  <joint name="z_revolute_joint" type="continuous">
    <limit effort="1000.0" velocity="10.0"/>
    <parent link="y_virtual_link"/>
    <child link="z_virtual_link"/>
    <axis xyz="0. 0. 1."/>
    <origin xyz="0.0 0.0 0.0" rpy="0.0 -0.0 0.0"/>
  </joint>
  <joint name="joint_mast" type="fixed">
    <parent link="base_link"/>
    <child link="link_mast"/>
    <axis xyz="1. 0. 0."/>
    <origin xyz="-0.067 0.135 0.0284" rpy="1.5708 0.0 4.8006e-17"/>
  </joint>
  <joint name="joint_lift" type="prismatic">
    <limit effort="100.0" velocity="1.0" lower="0.0" upper="1.1"/>
    <parent link="link_mast"/>
    <child link="link_lift"/>
    <axis xyz="0. 0. 1."/>
    <origin xyz="-0.037385 0.1666 0.0" rpy="1.5707926535897934 1.5707926535755432 -3.141592653589793"/>
  </joint>
  <joint name="joint_arm_l4" type="fixed">
    <parent link="link_lift"/>
    <child link="link_arm_l4"/>
    <axis xyz="1. 0. 0."/>
    <origin xyz="-0.2547 0.0 0.0" rpy="1.5708 2.4721e-15 -1.5708"/>
  </joint>
  <joint name="joint_arm_l3" type="prismatic">
    <limit effort="100.0" velocity="1.0" lower="0.0" upper="0.13"/>
    <parent link="link_arm_l4"/>
    <child link="link_arm_l3"/>
    <axis xyz="0. 0. 1."/>
    <origin xyz="0.0 0.0 0.013" rpy="7.68831233799385e-30 2.36716479416092e-30 2.29652732251143e-17"/>
  </joint>
  <joint name="joint_arm_l2" type="prismatic">
    <limit effort="100.0" velocity="1.0" lower="0.0" upper="0.13"/>
    <parent link="link_arm_l3"/>
    <child link="link_arm_l2"/>
    <axis xyz="0. 0. 1."/>
    <origin xyz="0.0 0.0 0.013" rpy="0.0 1.57655765344625e-30 -1.66533453693773e-16"/>
  </joint>
  <joint name="joint_arm_l1" type="prismatic">
    <limit effort="100.0" velocity="1.0" lower="0.0" upper="0.13"/>
    <parent link="link_arm_l2"/>
    <child link="link_arm_l1"/>
    <axis xyz="0. 0. 1."/>
    <origin xyz="0.0 0.0 0.0129999999999981" rpy="-7.63746778746202e-30 -7.88860905221012e-31 1.11022302462516e-16"/>
  </joint>
  <joint name="joint_arm_l0" type="prismatic">
    <limit effort="100.0" velocity="1.0" lower="0.0" upper="0.13"/>
    <parent link="link_arm_l1"/>
    <child link="link_arm_l0"/>
    <axis xyz="0. 0. 1."/>
    <origin xyz="0.0 0.0 -0.0137499999991968" rpy="7.63746778746202e-30 -3.80121128864402e-15 2.62707547767438e-15"/>
  </joint>
  <joint name="joint_wrist_yaw" type="revolute">
    <limit effort="100.0" velocity="1.0" lower="-1.75" upper="4.0"/>
    <parent link="link_arm_l0"/>
    <child link="link_wrist_yaw"/>
    <axis xyz=" 0.  0. -1."/>
    <origin xyz="0.0830000000000654 -0.0307500000000129 0.0" rpy="-1.5707963267949 0.0 3.14159265358978"/>
  </joint>
  <joint name="joint_wrist_yaw_bottom" type="fixed">
    <parent link="link_wrist_yaw"/>
    <child link="link_wrist_yaw_bottom"/>
    <axis xyz="1. 0. 0."/>
    <origin xyz="0.0 0.0 0.0" rpy="-3.14159265358979 0.0 -1.5707963267949"/>
  </joint>
  <joint name="joint_wrist_pitch" type="revolute">
    <limit effort="100.0" velocity="1.0" lower="-1.57" upper="0.56"/>
    <parent link="link_wrist_yaw_bottom"/>
    <child link="link_wrist_pitch"/>
    <axis xyz=" 0.  0. -1."/>
    <origin xyz="0.0 -0.019455 -0.0305" rpy="1.5708 0.0 -3.1415853071795867"/>
  </joint>
  <joint name="joint_wrist_roll" type="revolute">
    <limit effort="100.0" velocity="1.0" lower="-3.14" upper="3.14"/>
    <parent link="link_wrist_pitch"/>
    <child link="link_wrist_roll"/>
    <axis xyz="0. 0. 1."/>
    <origin xyz="-0.018859 -0.024 0.01955" rpy="7.3464102067096675e-06 1.5707926535755432 -3.141592653589793"/>
  </joint>
  <joint name="joint_gripper_s3_body" type="fixed">
    <parent link="link_wrist_roll"/>
    <child link="link_gripper_s3_body"/>
    <axis xyz="1. 0. 0."/>
    <origin xyz="0.0 0.0 0.0209999999993159" rpy="0.0 0.0 -3.14159265358975"/>
  </joint>
  <joint name="joint_gripper_finger_right" type="fixed">
    <limit effort="0.0" velocity="0.0" lower="0.0" upper="0.0"/>
    <parent link="link_gripper_s3_body"/>
    <child link="link_gripper_finger_right"/>
    <axis xyz="0. 0. 1."/>
    <origin xyz="-0.0246929393014972 0.0 0.0371909405167257" rpy="-1.57079632679513 1.4878931873251502 3.14159265358956"/>
  </joint>
  <joint name="joint_gripper_fingertip_right" type="fixed">
    <parent link="link_gripper_finger_right"/>
    <child link="link_gripper_fingertip_right"/>
    <axis xyz="1. 0. 0."/>
    <origin xyz="-0.177784508377902 -0.0106721811879468 0.0" rpy="-1.5707963267949 0.0 0.261799387799172"/>
  </joint>
  <joint name="joint_gripper_finger_left" type="fixed">
    <limit effort="0.0" velocity="0.0" lower="0.0" upper="0.0"/>
    <parent link="link_gripper_s3_body"/>
    <child link="link_gripper_finger_left"/>
    <axis xyz=" 0.  0. -1."/>
    <origin xyz="0.0245029393015013 0.0 0.0371909405167127" rpy="-1.57079632679523 -1.4878931873467196 -3.14159265358946"/>
  </joint>
  <joint name="joint_gripper_fingertip_left" type="fixed">
    <parent link="link_gripper_finger_left"/>
    <child link="link_gripper_fingertip_left"/>
    <axis xyz="1. 0. 0."/>
    <origin xyz="0.177784508377884 -0.0106721811879429 0.0" rpy="1.57079632679491 0.0 2.87979326579064"/>
  </joint>
  <joint name="joint_grasp_center" type="fixed">
    <parent link="link_gripper_s3_body"/>
    <child link="link_grasp_center"/>
    <axis xyz="1. 0. 0."/>
    <origin xyz="0.0 0.0 0.23" rpy="-1.5707963267949 -1.5707963267948966 0.0"/>
  </joint>
  <material name="aluminum">
    <color rgba="0.5 0.5 0.5 1. "/>
  </material>
  <material name="plastic">
    <color rgba="0.1 0.1 0.1 1. "/>
  </material>
  <material name="">
    <color rgba="0.79216 0.81961 0.93333 1.     "/>
  </material>
</robot>
