<?xml version="1.0" ?>
<!-- =================================================================================== -->
<!-- |    This document was autogenerated by xacro from urdf/stretch_description.xacro | -->
<!-- |    EDITING THIS FILE BY HAND IS NOT RECOMMENDED                                 | -->
<!-- =================================================================================== -->
<robot name="stretch">
  <!--<xacro:include filename="stretch_gripper_with_puller.xacro" />-->
  <!--<xacro:include filename="stretch_dry_erase_marker.xacro" />-->

  <link name="virtual_base" />
  <!-- Joint for translation in x-direction of base_link frame -->
  <joint name="x_prismatic_joint" type="fixed">
    <parent link="virtual_base"/>
    <child link="x_virtual_link"/>
    <origin rpy="0 0 0" xyz="0 0 0"/>
    <axis xyz="1 0 0"/>
    <limit lower="-100.0" upper="100.0" effort="10" velocity="1"/>
  </joint>

  <!-- Virtual link after x translation -->
  <link name="x_virtual_link" />

  <!-- Joint for translation in y-direction -->
  <joint name="y_prismatic_joint" type="fixed">
    <parent link="x_virtual_link"/>
    <child link="y_virtual_link"/>
    <origin rpy="0 0 0" xyz="0 0 0"/>
    <axis xyz="0 1 0"/>
    <limit lower="-100.0" upper="100.0" effort="1" velocity="1.0"/>
  </joint>

  <!-- Virtual link after y translation -->
  <link name="y_virtual_link" />

  <!-- Joint for rotation in z-direction -->
  <joint name="z_revolute_joint" type="fixed">
    <parent link="y_virtual_link"/>
    <child link="z_virtual_link"/>
    <origin rpy="0 0 0" xyz="0 0 0"/>
    <axis xyz="0 0 1"/>
    <limit effort="1000" velocity="10"/>
  </joint>

  <!-- Virtual link after z rotation -->
  <link name="z_virtual_link" >
    <inertial>
      <origin rpy="0 0 0" xyz="0 0 0"/>
      <mass value="1.0723782659782"/>
      <inertia ixx="0.00310580907710135" ixy="1.5182848191076E-06" ixz="0.00041690466732394" iyy="0.00433798719991832" iyz="1.33487716258445E-05" izz="0.0037204727467362"/>
    </inertial>
  </link>

  <joint name="virtual_base" type="fixed">
    <parent link="z_virtual_link"/>
    <child link="base_link"/>
    <axis xyz="0 0 0"/>
  </joint>
  
  <link name="base_link">
    <inertial>
      <origin rpy="0 0 0" xyz="-0.109461304328163 -0.000741018909047708 0.0914915269429946"/>
      <mass value="1.0723782659782"/>
      <inertia ixx="0.00310580907710135" ixy="1.5182848191076E-06" ixz="0.00041690466732394" iyy="0.00433798719991832" iyz="1.33487716258445E-05" izz="0.0037204727467362"/>
    </inertial>
    <visual>
      <origin rpy="0 0 0" xyz="0 0 0"/>
      <geometry>
        <mesh filename="../meshes/base_link.STL"/>
      </geometry>
      <material name="">
        <color rgba="0.792156862745098 0.819607843137255 0.933333333333333 1"/>
      </material>
    </visual>
    <collision>
      <origin rpy="0 0 0" xyz="0 0 0"/>
      <geometry>
        <mesh filename="/home/michal/Desktop/mobile_manip_test/meshes/base_link.STL"/>
      </geometry>
    </collision>
  </link>

  <joint name="base_mast" type="fixed">
    <parent link="base_link"/>
    <child link="link_mast"/>
    <origin rpy="1.5707963267949 0 0" xyz="-0.07 0.134999999999998 0.0284000000000001"/>
    <axis xyz="0 0 0"/>
  </joint>

  <link
    name="link_mast">
    <inertial>
      <origin
        xyz="0.00755818572975822 0.773971284176834 0.00647313086620024"
        rpy="0 0 0" />
      <mass
        value="0.749143203376401" />
      <inertia
        ixx="0.0709854511954588"
        ixy="-0.00433428742758457"
        ixz="-0.000186110788697573"
        iyy="0.000437922053342648"
        iyz="-0.00288788257713431"
        izz="0.071104808501661" />
    </inertial>
    <visual>
      <origin
        xyz="0 0 0"
        rpy="0 0 0" />
      <geometry>
        <mesh
          filename="/home/michal/Desktop/mobile_manip_test/meshes/link_mast.STL" />
      </geometry>
      <material
        name="">
        <color
          rgba="0.792156862745098 0.819607843137255 0.933333333333333 1" />
      </material>
    </visual>
    <collision>
      <origin
        xyz="0 0 0"
        rpy="0 0 0" />
      <geometry>
        <mesh
          filename="/home/michal/Desktop/mobile_manip_test/meshes/link_mast.STL" />
      </geometry>
    </collision>
  </link>
  <link name="link_lift">
    <inertial>
      <origin rpy="0 0 0" xyz="-0.0547636346252869 0.0380939689802074 0.00933159404448308"/>
      <mass value="0.444820831236007"/>
      <inertia ixx="0.000567192946271367" ixy="-0.00024607534789508" ixz="-0.000128108442260574" iyy="0.00127108364478659" iyz="7.61916855070339E-06" izz="0.00137296635099006"/>
    </inertial>
    <visual>
      <origin rpy="0 0 0" xyz="0 0 0"/>
      <geometry>
        <mesh filename="/home/michal/Desktop/mobile_manip_test/meshes/link_lift.STL"/>
      </geometry>
      <material name="">
        <color rgba="0.792156862745098 0.819607843137255 0.933333333333333 1"/>
      </material>
    </visual>
    <collision>
      <origin rpy="0 0 0" xyz="0 0 0"/>
      <geometry>
        <mesh filename="/home/michal/Desktop/mobile_manip_test/meshes/link_lift.STL"/>
      </geometry>
    </collision>
  </link>
  <joint name="joint_lift" type="prismatic">
    <origin rpy="-1.57079632679552 1.5615431375292 -6.2942004366467E-13" xyz="-0.0369217062323472 0.165471199999996 -0.000341653286793524"/>
    <parent link="link_mast"/>
    <child link="link_lift"/>
    <axis xyz="0 0 1"/>
    <!-- for now: hand copied range_m: from lift: from ~/repos/stretch_fleet/stretch-re1-1001/stretch_re1_factory_params.yaml -->
    <!--<limit effort="100" lower="0.0" upper="1.095" velocity="1.0"/>-->
    <!-- copied value did not reach the top of mesh model with GUI sliders and RViz -->
    <limit effort="100" lower="0.0" upper="1.1" velocity="1.0"/>
  </joint>
  <link name="link_arm_l4">
    <inertial>
      <origin rpy="0 0 0" xyz="-1.61247276464493E-06 1.54715589201215E-06 -0.0953252706040035"/>
      <mass value="0.0676525455789735"/>
      <inertia ixx="0.000122002023066796" ixy="7.29593356230121E-13" ixz="9.63170353371061E-09" iyy="0.000122002023127152" iyz="-9.24154949889042E-09" izz="1.46043439809638E-12"/>
    </inertial>
    <visual>
      <origin rpy="0 0 0" xyz="0 0 0"/>
      <geometry>
        <mesh filename="/home/michal/Desktop/mobile_manip_test/meshes/link_arm_l4.STL"/>
      </geometry>
      <material name="">
        <color rgba="0.792156862745098 0.819607843137255 0.933333333333333 1"/>
      </material>
    </visual>
    <collision>
      <origin rpy="0 0 0" xyz="0 0 0"/>
      <geometry>
        <mesh filename="/home/michal/Desktop/mobile_manip_test/meshes/link_arm_l4.STL"/>
      </geometry>
    </collision>
  </link>
  <joint name="joint_arm_l4" type="fixed">
    <origin rpy="1.5708 -3.1019E-16 -1.5708" xyz="-0.25471 0 0"/>
    <parent link="link_lift"/>
    <child link="link_arm_l4"/>
    <axis xyz="0 0 0"/>
  </joint>
  <link name="link_arm_l3">
    <inertial>
      <origin rpy="0 0 0" xyz="-3.34873468621488E-07 4.7411336306924E-07 -0.0974069598289041"/>
      <mass value="0.0626921047058405"/>
      <inertia ixx="0.001" ixy="0" ixz="0" iyy="0.001" iyz="0" izz="0.001"/>
    </inertial>
    <visual>
      <origin rpy="0 0 0" xyz="0 0 0"/>
      <geometry>
        <mesh filename="/home/michal/Desktop/mobile_manip_test/meshes/link_arm_l3.STL"/>
      </geometry>
      <material name="">
        <color rgba="0.792156862745098 0.819607843137255 0.933333333333333 1"/>
      </material>
    </visual>
    <collision>
      <origin rpy="0 0 0" xyz="0 0 0"/>
      <geometry>
        <mesh filename="/home/michal/Desktop/mobile_manip_test/meshes/link_arm_l3.STL"/>
      </geometry>
    </collision>
  </link>
  <joint name="joint_arm_l3" type="prismatic">
    <origin rpy="3.5742E-16 3.2123E-16 -2.4565E-16" xyz="0 0 0.013"/>
    <parent link="link_arm_l4"/>
    <child link="link_arm_l3"/>
    <axis xyz="0 0 1"/>
    <!-- 0.13 = 0.52/4-->
    <limit effort="100" lower="0.0" upper="0.13" velocity="1.0"/>
  </joint>
  <link name="link_arm_l2">
    <inertial>
      <origin rpy="0 0 0" xyz="-3.31043560508615E-07 3.13422303999111E-07 -0.097255883541891"/>
      <mass value="0.0569074368576238"/>
      <inertia ixx="0.001" ixy="0" ixz="0" iyy="0.001" iyz="0" izz="0.001"/>
    </inertial>
    <visual>
      <origin rpy="0 0 0" xyz="0 0 0"/>
      <geometry>
        <mesh filename="/home/michal/Desktop/mobile_manip_test/meshes/link_arm_l2.STL"/>
      </geometry>
      <material name="">
        <color rgba="0.792156862745098 0.819607843137255 0.933333333333333 1"/>
      </material>
    </visual>
    <collision>
      <origin rpy="0 0 0" xyz="0 0 0"/>
      <geometry>
        <mesh filename="/home/michal/Desktop/mobile_manip_test/meshes/link_arm_l2.STL"/>
      </geometry>
    </collision>
  </link>
  <joint name="joint_arm_l2" type="prismatic">
    <origin rpy="2.91385731014123E-16 4.44300759504684E-17 3.25691080516352E-16" xyz="0 0 0.013"/>
    <parent link="link_arm_l3"/>
    <child link="link_arm_l2"/>
    <axis xyz="0 0 1"/>
    <!-- 0.13 = 0.52/4-->
    <limit effort="100" lower="0.0" upper="0.13" velocity="1.0"/>
  </joint>
  <link name="link_arm_l1">
    <inertial>
      <origin rpy="0 0 0" xyz="-3.36876635420591E-07 3.05876091066803E-07 -0.0969117032232756"/>
      <mass value="0.0511763619538321"/>
      <inertia ixx="0.001" ixy="0" ixz="0" iyy="0.001" iyz="0" izz="0.001"/>
    </inertial>
    <visual>
      <origin rpy="0 0 0" xyz="0 0 0"/>
      <geometry>
        <mesh filename="/home/michal/Desktop/mobile_manip_test/meshes/link_arm_l1.STL"/>
      </geometry>
      <material name="">
        <color rgba="0.792156862745098 0.819607843137255 0.933333333333333 1"/>
      </material>
    </visual>
    <collision>
      <origin rpy="0 0 0" xyz="0 0 0"/>
      <geometry>
        <mesh filename="/home/michal/Desktop/mobile_manip_test/meshes/link_arm_l1.STL"/>
      </geometry>
    </collision>
  </link>
  <joint name="joint_arm_l1" type="prismatic">
    <origin rpy="7.41596560408007E-17 1.33876788296791E-16 -2.44545873596083E-16" xyz="0 0 0.013"/>
    <parent link="link_arm_l2"/>
    <child link="link_arm_l1"/>
    <axis xyz="0 0 1"/>
    <!-- 0.13 = 0.52/4-->
    <limit effort="100" lower="0.0" upper="0.13" velocity="1.0"/>
  </joint>
  <link name="link_arm_l0">
    <inertial>
      <origin rpy="0 0 0" xyz="0.0230715049668191 -0.00195115833662818 -0.0360646347160285"/>
      <mass value="0.101241250325294"/>
      <inertia ixx="0.001" ixy="0" ixz="0" iyy="0.001" iyz="0" izz="0.001"/>
    </inertial>
    <visual>
      <origin rpy="0 0 0" xyz="0 0 0"/>
      <geometry>
        <mesh filename="/home/michal/Desktop/mobile_manip_test/meshes/link_arm_l0.STL"/>
      </geometry>
      <material name="">
        <color rgba="0.792156862745098 0.819607843137255 0.933333333333333 1"/>
      </material>
    </visual>
    <collision>
      <origin rpy="0 0 0" xyz="0 0 0"/>
      <geometry>
        <mesh filename="/home/michal/Desktop/mobile_manip_test/meshes/link_arm_l0.STL"/>
      </geometry>
    </collision>
  </link>
  <joint name="joint_arm_l0" type="prismatic">
    <origin rpy="-3.05317390622457E-16 -4.23236224076729E-16 -2.68425135229209E-17" xyz="0 0 -0.0137499999999938"/>
    <parent link="link_arm_l1"/>
    <child link="link_arm_l0"/>
    <axis xyz="0 0 1"/>
    <!-- 0.13 = 0.52/4-->
    <limit effort="100" lower="0.0" upper="0.13" velocity="1.0"/>
  </joint>
  <link name="link_wrist_yaw">
    <inertial>
      <origin rpy="0 0 0" xyz="-8.02795716750571E-06 1.93811447768422E-05 0.018946700595851"/>
      <mass value="0.0405398981326229"/>
      <inertia ixx="0.001" ixy="0" ixz="0" iyy="0.001" iyz="0" izz="0.001"/>
    </inertial>
    <visual>
      <origin rpy="0 0 0" xyz="0 0 0"/>
      <geometry>
        <mesh filename="/home/michal/Desktop/mobile_manip_test/meshes/link_wrist_yaw.STL"/>
      </geometry>
      <material name="">
        <color rgba="0.792156862745098 0.819607843137255 0.933333333333333 1"/>
      </material>
    </visual>
    <collision>
      <origin rpy="0 0 0" xyz="0 0 0"/>
      <geometry>
        <mesh filename="/home/michal/Desktop/mobile_manip_test/meshes/link_wrist_yaw.STL"/>
      </geometry>
    </collision>
  </link>
  <joint name="joint_wrist_yaw" type="revolute">
    <origin rpy="1.5708 4.2595E-14 2.6415E-15" xyz="0.083 -0.03075 0"/>
    <parent link="link_arm_l0"/>
    <child link="link_wrist_yaw"/>
    <axis xyz="0 0 -1"/>
    <!--
      stowed to front ~225 deg: 3.15159 x 1.25 = 3.9395
      using 4.0
      stowed to back ~100 deg:  100 / 180 x 3.14159 = 1.7453
      using -1.75
    -->
    <limit effort="100" lower="-1.75" upper="4.0" velocity="1.0"/>
  </joint>
  <link name="link_gripper">
    <inertial>
      <origin rpy="0 0 0" xyz="-0.0170229132730066 0.0131410320934285 -0.0371614759484659"/>
      <mass value="0.101902711393094"/>
      <inertia ixx="0.001" ixy="0" ixz="0" iyy="0.001" iyz="0" izz="0.001"/>
    </inertial>
    <visual>
      <origin rpy="0 0 0" xyz="0 0 0"/>
      <geometry>
        <mesh filename="/home/michal/Desktop/mobile_manip_test/meshes/link_gripper.STL"/>
      </geometry>
      <material name="">
        <color rgba="0.792156862745098 0.819607843137255 0.933333333333333 1"/>
      </material>
    </visual>
    <collision>
      <origin rpy="0 0 0" xyz="0 0 0"/>
      <geometry>
        <mesh filename="/home/michal/Desktop/mobile_manip_test/meshes/link_gripper.STL"/>
      </geometry>
    </collision>
  </link>
  <!-- rpy="3.1416 0 1.5708" -->
  <!-- rpy="0.0 0 1.5708" -->
  <joint name="joint_gripper" type="fixed">
    <origin rpy="3.14159 0 -1.5708" xyz="0 0 0"/>
    <parent link="link_wrist_yaw"/>
    <child link="link_gripper"/>
    <axis xyz="0 0 0"/>
  </joint>
  <link name="link_gripper_finger_left">
    <inertial>
      <origin rpy="0 0 0" xyz="0.0945047483510102 0.0124301080924361 -4.44089209850063E-16"/>
      <mass value="0.0476207785199474"/>
      <inertia ixx="0.001" ixy="0" ixz="0" iyy="0.001" iyz="0" izz="0.001"/>
    </inertial>
    <visual>
      <origin rpy="0 0 0" xyz="0 0 0"/>
      <geometry>
        <mesh filename="/home/michal/Desktop/mobile_manip_test/meshes/link_gripper_finger_left.STL" scale="0.9 1.0 1.0"/>
      </geometry>
      <material name="">
        <color rgba="0.792156862745098 0.819607843137255 0.933333333333333 1"/>
      </material>
    </visual>
    <collision>
      <origin rpy="0 0 0" xyz="0 0 0"/>
      <geometry>
        <mesh filename="/home/michal/Desktop/mobile_manip_test/meshes/link_gripper_finger_left.STL" scale="0.9 1.0 1.0"/>
      </geometry>
    </collision>
  </link>
  <joint name="joint_gripper_finger_left" type="fixed">
    <origin rpy="2.1762E-15 0.5236 3.1416" xyz="-0.047231 -0.010151 -0.04679"/>
    <parent link="link_gripper"/>
    <child link="link_gripper_finger_left"/>
    <axis xyz="0 0 1"/>
  </joint>
  <link name="link_gripper_fingertip_left">
    <inertial>
      <origin rpy="0 0 0" xyz="-3.16381381648689E-08 -2.91408530639359E-09 0.00812579670381812"/>
      <mass value="0.00382159917455729"/>
      <inertia ixx="0.001" ixy="0" ixz="0" iyy="0.001" iyz="0" izz="0.001"/>
    </inertial>
    <visual>
      <origin rpy="0 0 0" xyz="0 0 0"/>
      <geometry>
        <mesh filename="/home/michal/Desktop/mobile_manip_test/meshes/link_gripper_fingertip_left.STL"/>
      </geometry>
      <material name="">
        <color rgba="0.250980392156863 0.250980392156863 0.250980392156863 1"/>
      </material>
    </visual>
    <collision>
      <origin rpy="0 0 0" xyz="0 0 0"/>
      <geometry>
        <mesh filename="/home/michal/Desktop/mobile_manip_test/meshes/link_gripper_fingertip_left.STL"/>
      </geometry>
    </collision>
  </link>
  <joint name="joint_gripper_fingertip_left" type="fixed">
    <origin rpy="-1.5708 -4.774E-15 -2.5545" xyz="0.171099 0.014912 0"/>
    <parent link="link_gripper_finger_left"/>
    <child link="link_gripper_fingertip_left"/>
    <axis xyz="0 0 0"/>
  </joint>
  <link name="link_gripper_finger_right">
    <inertial>
      <origin rpy="0 0 0" xyz="-0.0945047483510099 -0.0124301080924345 0"/>
      <mass value="0.0476207785199481"/>
      <inertia ixx="0.001" ixy="0" ixz="0" iyy="0.001" iyz="0" izz="0.001"/>
    </inertial>
    <visual>
      <origin rpy="0 0 0" xyz="0 0 0"/>
      <geometry>
        <mesh filename="/home/michal/Desktop/mobile_manip_test/meshes/link_gripper_finger_right.STL" scale="0.9 1.0 1.0"/>
      </geometry>
      <material name="">
        <color rgba="0.792156862745098 0.819607843137255 0.933333333333333 1"/>
      </material>
    </visual>
    <collision>
      <origin rpy="0 0 0" xyz="0 0 0"/>
      <geometry>
        <mesh filename="/home/michal/Desktop/mobile_manip_test/meshes/link_gripper_finger_right.STL" scale="0.9 1.0 1.0"/>
      </geometry>
    </collision>
  </link>
  <joint name="joint_gripper_finger_right" type="fixed">
    <origin rpy="3.1416 -0.5236 1.2943E-15" xyz="-0.047231 0.010049 -0.04679"/>
    <parent link="link_gripper"/>
    <child link="link_gripper_finger_right"/>
    <axis xyz="0 0 1"/>
  </joint>
  <link name="link_gripper_fingertip_right">
    <inertial>
      <origin rpy="0 0 0" xyz="2.59386303963494E-08 6.70949018566347E-09 0.00812579516130402"/>
      <mass value="0.00382160037319545"/>
      <inertia ixx="0.001" ixy="0" ixz="0" iyy="0.001" iyz="0" izz="0.001"/>
    </inertial>
    <visual>
      <origin rpy="0 0 0" xyz="0 0 0"/>
      <geometry>
        <mesh filename="/home/michal/Desktop/mobile_manip_test/meshes/link_gripper_fingertip_right.STL"/>
      </geometry>
      <material name="">
        <color rgba="0.250980392156863 0.250980392156863 0.250980392156863 1"/>
      </material>
    </visual>
    <collision>
      <origin rpy="0 0 0" xyz="0 0 0"/>
      <geometry>
        <mesh filename="/home/michal/Desktop/mobile_manip_test/meshes/link_gripper_fingertip_right.STL"/>
      </geometry>
    </collision>
  </link>
  <joint name="joint_gripper_fingertip_right" type="fixed">
    <origin rpy="-1.5708 -2.0539E-15 0.58705" xyz="-0.171099 -0.014912 0"/>
    <parent link="link_gripper_finger_right"/>
    <child link="link_gripper_fingertip_right"/>
    <axis xyz="0 0 0"/>
  </joint>
  <link name="link_grasp_center">
  </link>
  <joint name="joint_grasp_center" type="fixed">
    <origin rpy="0 0 3.141579" xyz="-0.205478 0 -0.138154"/>
    <parent link="link_gripper"/>
    <child link="link_grasp_center"/>
  </joint>
</robot>
